Workbook

Sheet BART (popped)
A1: Order | B1: Day | C1: Time | D1: ID | E1: 1 | F1: 2 | G1: 3 | H1: 4 | I1: 5 | J1: 6 | K1: 7 | L1: 8 | M1: 9 | N1: 10 | O1: 11 | P1: 12 | Q1: 13 | R1: 14 | S1: 15 | T1: 16 | U1: 17 | V1: 18 | W1: 19 | X1: 20 | Y1: Popped
A2: 1 | B2: 45484 | C2: 17h12 | D2: AM01071945 | E2: FALSO | F2: FALSO | G2: FALSO | H2: FALSO | I2: FALSO | J2: VERDADEIRO | K2: FALSO | L2: FALSO | M2: FALSO | N2: FALSO | O2: FALSO | P2: VERDADEIRO | Q2: FALSO | R2: FALSO | S2: FALSO | T2: FALSO | U2: FALSO | V2: FALSO | W2: VERDADEIRO | X2: FALSO | Y2: =COUNTIF(E2:X2,"VERDADEIRO") -> 3
A3: 2 | B3: 45490 | C3: 14h52 | D3: AP17091950 | E3: FALSO | F3: FALSO | G3: FALSO | H3: FALSO | I3: VERDADEIRO | J3: FALSO | K3: FALSO | L3: FALSO | M3: VERDADEIRO | N3: FALSO | O3: FALSO | P3: VERDADEIRO | Q3: FALSO | R3: FALSO | S3: FALSO | T3: VERDADEIRO | U3: FALSO | V3: FALSO | W3: FALSO | X3: FALSO | Y3: =COUNTIF(E3:X3,"VERDADEIRO") -> 4
A4: 3 | B4: 45477 | C4: 15h34 | D4: AR10061960 | E4: FALSO | F4: FALSO | G4: FALSO | H4: FALSO | I4: FALSO | J4: FALSO | K4: VERDADEIRO | L4: FALSO | M4: VERDADEIRO | N4: FALSO | O4: FALSO | P4: FALSO | Q4: VERDADEIRO | R4: VERDADEIRO | S4: FALSO | T4: FALSO | U4: FALSO | V4: FALSO | W4: FALSO | X4: VERDADEIRO | Y4: =COUNTIF(E4:X4,"VERDADEIRO") -> 5
A5: 4 | B5: 45482 | C5: 16h59 | D5: EM22071954 | E5: VERDADEIRO | F5: FALSO | G5: FALSO | H5: FALSO | I5: VERDADEIRO | J5: FALSO | K5: FALSO | L5: VERDADEIRO | M5: VERDADEIRO | N5: FALSO | O5: FALSO | P5: FALSO | Q5: FALSO | R5: FALSO | S5: FALSO | T5: VERDADEIRO | U5: FALSO | V5: FALSO | W5: FALSO | X5: FALSO | Y5: =COUNTIF(E5:X5,"VERDADEIRO") -> 5
A6: 5 | B6: 45477 | C6: 16h20 | D6: ES21111948 | E6: FALSO | F6: FALSO | G6: FALSO | H6: FALSO | I6: FALSO | J6: FALSO | K6: FALSO | L6: FALSO | M6: FALSO | N6: FALSO | O6: FALSO | P6: FALSO | Q6: FALSO | R6: FALSO | S6: FALSO | T6: FALSO | U6: FALSO | V6: FALSO | W6: FALSO | X6: FALSO | Y6: =COUNTIF(E6:X6,"VERDADEIRO") -> 0
A7: 6 | B7: 45484 | C7: 11h57 | D7: FR24011951 | E7: FALSO | F7: FALSO | G7: FALSO | H7: FALSO | I7: FALSO | J7: FALSO | K7: FALSO | L7: FALSO | M7: VERDADEIRO | N7: FALSO | O7: FALSO | P7: VERDADEIRO | Q7: FALSO | R7: FALSO | S7: VERDADEIRO | T7: VERDADEIRO | U7: FALSO | V7: FALSO | W7: FALSO | X7: VERDADEIRO | Y7: =COUNTIF(E7:X7,"VERDADEIRO") -> 5
A8: 7 | B8: 45477 | C8: 16h14 | D8: JM19101961 | E8: FALSO | F8: VERDADEIRO | G8: FALSO | H8: FALSO | I8: FALSO | J8: FALSO | K8: FALSO | L8: FALSO | M8: VERDADEIRO | N8: VERDADEIRO | O8: FALSO | P8: FALSO | Q8: FALSO | R8: FALSO | S8: FALSO | T8: FALSO | U8: FALSO | V8: FALSO | W8: FALSO | X8: FALSO | Y8: =COUNTIF(E8:X8,"VERDADEIRO") -> 3
A9: 8 | B9: 45475 | C9: 15h28 | D9: JS21021941 | E9: FALSO | F9: FALSO | G9: FALSO | H9: FALSO | I9: FALSO | J9: FALSO | K9: FALSO | L9: FALSO | M9: FALSO | N9: FALSO | O9: VERDADEIRO | P9: FALSO | Q9: FALSO | R9: FALSO | S9: FALSO | T9: FALSO | U9: FALSO | V9: FALSO | W9: FALSO | X9: FALSO | Y9: =COUNTIF(E9:X9,"VERDADEIRO") -> 1
A10: 9 | B10: 45490 | C10: 15h51 | D10: JV11091949 | E10: FALSO | F10: FALSO | G10: FALSO | H10: VERDADEIRO | I10: FALSO | J10: FALSO | K10: FALSO | L10: FALSO | M10: FALSO | N10: FALSO | O10: VERDADEIRO | P10: FALSO | Q10: VERDADEIRO | R10: VERDADEIRO | S10: FALSO | T10: FALSO | U10: FALSO | V10: FALSO | W10: VERDADEIRO | X10: FALSO | Y10: =COUNTIF(E10:X10,"VERDADEIRO") -> 5
A11: 10 | B11: 45482 | C11: 15h46 | D11: MA30061957 | E11: FALSO | F11: FALSO | G11: FALSO | H11: FALSO | I11: FALSO | J11: FALSO | K11: FALSO | L11: FALSO | M11: VERDADEIRO | N11: FALSO | O11: FALSO | P11: VERDADEIRO | Q11: VERDADEIRO | R11: FALSO | S11: FALSO | T11: FALSO | U11: FALSO | V11: VERDADEIRO | W11: FALSO | X11: FALSO | Y11: =COUNTIF(E11:X11,"VERDADEIRO") -> 4
A12: 11 | B12: 45482 | C12: 12h02 | D12: MG06041942 | E12: FALSO | F12: FALSO | G12: FALSO | H12: FALSO | I12: VERDADEIRO | J12: VERDADEIRO | K12: FALSO | L12: FALSO | M12: FALSO | N12: FALSO | O12: FALSO | P12: FALSO | Q12: FALSO | R12: FALSO | S12: VERDADEIRO | T12: VERDADEIRO | U12: FALSO | V12: FALSO | W12: FALSO | X12: VERDADEIRO | Y12: =COUNTIF(E12:X12,"VERDADEIRO") -> 5
A13: 12 | B13: 45484 | C13: 17h23 | D13: ML15061931 | E13: FALSO | F13: FALSO | G13: FALSO | H13: FALSO | I13: FALSO | J13: VERDADEIRO | K13: VERDADEIRO | L13: FALSO | M13: FALSO | N13: FALSO | O13: FALSO | P13: FALSO | Q13: FALSO | R13: FALSO | S13: FALSO | T13: FALSO | U13: FALSO | V13: FALSO | W13: FALSO | X13: FALSO | Y13: =COUNTIF(E13:X13,"VERDADEIRO") -> 2
... A28: 27 | B28: 45511 | C28: 15h23 | D28: OS11071966 | E28: VERDADEIRO | F28: FALSO | G28: FALSO | H28: FALSO | I28: FALSO | J28: FALSO | K28: FALSO | L28: FALSO | M28: VERDADEIRO | N28: FALSO | O28: FALSO | P28: FALSO | Q28: FALSO | R28: FALSO | S28: FALSO | T28: FALSO | U28: FALSO | V28: VERDADEIRO | W28: FALSO | X28: VERDADEIRO | Y28: =COUNTIF(E28:X28,"VERDADEIRO") -> 4
A29: 28
A30: 29

Sheet BART score
A1: Day | B1: Time | C1: ID | D1: 1 | E1: 2 | F1: 3 | G1: 4 | H1: 5 | I1: 6 | J1: 7 | K1: 8 | L1: 9 | M1: 10 | N1: 11 | O1: 12 | P1: 13 | Q1: 14 | R1: 15 | S1: 16 | T1: 17 | U1: 18 | V1: 19 | W1: 20 | X1: FinalScore
A2: 45484 | B2: 17h12 | C2: AM01071945 | D2: 8 | E2: 10 | F2: 14 | G2: 14 | H2: 20 | I2: 25 | J2: 10 | K2: 20 | L2: 14 | M2: 16 | N2: 16 | O2: 9 | P2: 16 | Q2: 18 | R2: 18 | S2: 14 | T2: 16 | U2: 18 | V2: 11 | W2: 20 | X2: 131
A3: 45490 | B3: 14h52 | C3: AP17091950 | D3: 30 | E3: 30 | F3: 30 | G3: 30 | H3: 16 | I3: 30 | J3: 30 | K3: 34 | L3: 9 | M3: 24 | N3: 24 | O3: 10 | P3: 30 | Q3: 20 | R3: 42 | S3: 2 | T3: 30 | U3: 30 | V3: 30 | W3: 30 | X3: 237
A4: 45477 | B4: 15h34 | C4: AR10061960 | D4: 20 | E4: 30 | F4: 30 | G4: 33 | H4: 32 | I4: 34 | J4: 19 | K4: 30 | L4: 3 | M4: 30 | N4: 30 | O4: 30 | P4: 30 | Q4: 11 | R4: 24 | S4: 31 | T4: 25 | U4: 20 | V4: 20 | W4: 8 | X4: 209.5
A5: 45482 | B5: 16h59 | C5: EM22071954 | D5: 31 | E5: 21 | F5: 28 | G5: 37 | H5: 21 | I5: 40 | J5: 42 | K5: 4 | L5: 40 | M5: 30 | N5: 30 | O5: 35 | P5: 40 | Q5: 42 | R5: 42 | S5: 10 | T5: 42 | U5: 40 | V5: 43 | W5: 44 | X5: 278
A6: 45477 | B6: 16h20 | C6: ES21111948 | D6: 4 | E6: 7 | F6: 7 | G6: 8 | H6: 8 | I6: 8 | J6: 7 | K6: 9 | L6: 10 | M6: 10 | N6: 10 | O6: 10 | P6: 9 | Q6: 10 | R6: 11 | S6: 11 | T6: 12 | U6: 8 | V6: 9 | W6: 11 | X6: 89.5
A7: 45484 | B7: 11h57 | C7: FR24011951 | D7: 15 | E7: 10 | F7: 18 | G7: 13 | H7: 20 | I7: 40 | J7: 51 | K7: 84 | L7: 12 | M7: 51 | N7: 100 | O7: 9 | P7: 46 | Q7: 28 | R7: 18 | S7: 4 | T7: 26 | U7: 14 | V7: 19 | W7: 13 | X7: 267.5
A8: 45477 | B8: 16h14 | C8: JM19101961 | D8: 19 | E8: 14 | F8: 10 | G8: 9 | H8: 10 | I8: 10 | J8: 10 | K8: 13 | L8: 6 | M8: 5 | N8: 4 | O8: 7 | P8: 9 | Q8: 7 | R8: 9 | S8: 7 | T8: 9 | U8: 7 | V8: 9 | W8: 10 | X8: 79.5
A9: 45475 | B9: 15h28 | C9: JS21021941 | D9: 4 | E9: 10 | F9: 6 | G9: 8 | H9: 6 | I9: 12 | J9: 10 | K9: 10 | L9: 10 | M9: 8 | N9: 12 | O9: 5 | P9: 4 | Q9: 6 | R9: 8 | S9: 6 | T9: 6 | U9: 6 | V9: 8 | W9: 6 | X9: 70.5
A10: 45490 | B10: 15h51 | C10: JV11091949 | D10: 16 | E10: 20 | F10: 22 | G10: 13 | H10: 16 | I10: 18 | J10: 15 | K10: 16 | L10: 15 | M10: 15 | N10: 6 | O10: 15 | P10: 5 | Q10: 3 | R10: 12 | S10: 15 | T10: 15 | U10: 13 | V10: 10 | W10: 14 | X10: 118.5
A11: 45482 | B11: 15h46 | C11: MA30061957 | D11: 20 | E11: 30 | F11: 40 | G11: 40 | H11: 50 | I11: 30 | J11: 40 | K11: 30 | L11: 20 | M11: 30 | N11: 20 | O11: 14 | P11: 12 | Q11: 20 | R11: 20 | S11: 20 | T11: 20 | U11: 8 | V11: 20 | W11: 20 | X11: 225
A12: 45482 | B12: 12h02 | C12: MG06041942 | D12: 8 | E12: 7 | F12: 8 | G12: 10 | H12: 9 | I12: 7 | J12: 5 | K12: 10 | L12: 11 | M12: 10 | N12: 15 | O12: 18 | P12: 23 | Q12: 27 | R12: 21 | S12: 13 | T12: 16 | U12: 25 | V12: 26 | W12: 14 | X12: 109.5
A13: 45484 | B13: 17h23 | C13: ML15061931 | D13: 20 | E13: 20 | F13: 20 | G13: 20 | H13: 20 | I13: 3 | J13: 6 | K13: 20 | L13: 20 | M13: 20 | N13: 20 | O13: 20 | P13: 20 | Q13: 20 | R13: 20 | S13: 20 | T13: 20 | U13: 20 | V13: 20 | W13: 20 | X13: 180
... A28: 45511 | B28: 15h23 | C28: OS11071966 | D28: 18 | E28: 12 | F28: 14 | G28: 18 | H28: 18 | I28: 15 | J28: 16 | K28: 19 | L28: 13 | M28: 18 | N28: 14 | O28: 15 | P28: 13 | Q28: 15 | R28: 15 | S28: 14 | T28: 16 | U28: 10 | V28: 18 | W28: 14 | X28: 125

Sheet BART finalData
A1: Day | B1: Time | C1: ID | D1: 1 | E1: 2 | F1: 3 | G1: 4 | H1: 5 | I1: 6 | J1: 7 | K1: 8 | L1: 9 | M1: 10 | N1: 11 | O1: 12 | P1: 13 | Q1: 14 | R1: 15 | S1: 16 | T1: 17 | U1: 18 | V1: 19 | W1: 20 | X1: Mean
A2: ='BART score'!A2 -> 45484 | B2: ='BART score'!B2 -> 17h12 | C2: ='BART score'!C2 -> AM01071945 | D2: =IF('BART (popped)'!E2="FALSO",'BART score'!D2,"") -> 8 | E2: =IF('BART (popped)'!F2="FALSO",'BART score'!E2,"") -> 10 | F2: =IF('BART (popped)'!G2="FALSO",'BART score'!F2,"") -> 14 | G2: =IF('BART (popped)'!H2="FALSO",'BART score'!G2,"") -> 14 | H2: =IF('BART (popped)'!I2="FALSO",'BART score'!H2,"") -> 20 | I2: =IF('BART (popped)'!J2="FALSO",'BART score'!I2,"") | J2: =IF('BART (popped)'!K2="FALSO",'BART score'!J2,"") -> 10 | K2: =IF('BART (popped)'!L2="FALSO",'BART score'!K2,"") -> 20 | ... W2: =IF('BART (popped)'!X2="FALSO",'BART score'!W2,"") -> 20 | X2: =AVERAGE(D2:W2) -> 15.411765
A3: ='BART score'!A3 -> 45490 | B3: ='BART score'!B3 -> 14h52 | C3: ='BART score'!C3 -> AP17091950 | D3: =IF('BART (popped)'!E3="FALSO",'BART score'!D3,"") -> 30 | E3: =IF('BART (popped)'!F3="FALSO",'BART score'!E3,"") -> 30 | F3: =IF('BART (popped)'!G3="FALSO",'BART score'!F3,"") -> 30 | G3: =IF('BART (popped)'!H3="FALSO",'BART score'!G3,"") -> 30 | H3: =IF('BART (popped)'!I3="FALSO",'BART score'!H3,"") | I3: =IF('BART (popped)'!J3="FALSO",'BART score'!I3,"") -> 30 | J3: =IF('BART (popped)'!K3="FALSO",'BART score'!J3,"") -> 30 | K3: =IF('BART (popped)'!L3="FALSO",'BART score'!K3,"") -> 34 | ... W3: =IF('BART (popped)'!X3="FALSO",'BART score'!W3,"") -> 30 | X3: =AVERAGE(D3:W3) -> 29.625
A4: ='BART score'!A8 -> 45477 | B4: ='BART score'!B8 -> 16h14 | C4: ='BART score'!C8 -> JM19101961 | D4: =IF('BART (popped)'!E8="FALSO",'BART score'!D8,"") -> 19 | E4: =IF('BART (popped)'!F8="FALSO",'BART score'!E8,"") | F4: =IF('BART (popped)'!G8="FALSO",'BART score'!F8,"") -> 10 | G4: =IF('BART (popped)'!H8="FALSO",'BART score'!G8,"") -> 9 | H4: =IF('BART (popped)'!I8="FALSO",'BART score'!H8,"") -> 10 | I4: =IF('BART (popped)'!J8="FALSO",'BART score'!I8,"") -> 10 | J4: =IF('BART (popped)'!K8="FALSO",'BART score'!J8,"") -> 10 | K4: =IF('BART (popped)'!L8="FALSO",'BART score'!K8,"") -> 13 | ... W4: =IF('BART (popped)'!X8="FALSO",'BART score'!W8,"") -> 10 | X4: =AVERAGE(D4:W4) -> 9.3529412
A5: ='BART score'!A12 -> 45482 | B5: ='BART score'!B12 -> 12h02 | C5: ='BART score'!C12 -> MG06041942 | D5: =IF('BART (popped)'!E12="FALSO",'BART score'!D12,"") -> 8 | E5: =IF('BART (popped)'!F12="FALSO",'BART score'!E12,"") -> 7 | F5: =IF('BART (popped)'!G12="FALSO",'BART score'!F12,"") -> 8 | G5: =IF('BART (popped)'!H12="FALSO",'BART score'!G12,"") -> 10 | H5: =IF('BART (popped)'!I12="FALSO",'BART score'!H12,"") | I5: =IF('BART (popped)'!J12="FALSO",'BART score'!I12,"") | J5: =IF('BART (popped)'!K12="FALSO",'BART score'!J12,"") -> 5 | K5: =IF('BART (popped)'!L12="FALSO",'BART score'!K12,"") -> 10 | ... W5: =IF('BART (popped)'!X12="FALSO",'BART score'!W12,"") | X5: =AVERAGE(D5:W5) -> 14.6
A6: ='BART score'!A13 -> 45484 | B6: ='BART score'!B13 -> 17h23 | C6: ='BART score'!C13 -> ML15061931 | D6: =IF('BART (popped)'!E13="FALSO",'BART score'!D13,"") -> 20 | E6: =IF('BART (popped)'!F13="FALSO",'BART score'!E13,"") -> 20 | F6: =IF('BART (popped)'!G13="FALSO",'BART score'!F13,"") -> 20 | G6: =IF('BART (popped)'!H13="FALSO",'BART score'!G13,"") -> 20 | H6: =IF('BART (popped)'!I13="FALSO",'BART score'!H13,"") -> 20 | I6: =IF('BART (popped)'!J13="FALSO",'BART score'!I13,"") | J6: =IF('BART (popped)'!K13="FALSO",'BART score'!J13,"") | K6: =IF('BART (popped)'!L13="FALSO",'BART score'!K13,"") -> 20 | ... W6: =IF('BART (popped)'!X13="FALSO",'BART score'!W13,"") -> 20 | X6: =AVERAGE(D6:W6) -> 20
A7: ='BART score'!A14 -> 45477 | B7: ='BART score'!B14 -> 15h44 | C7: ='BART score'!C14 -> MM18091956 | D7: =IF('BART (popped)'!E14="FALSO",'BART score'!D14,"") -> 13 | E7: =IF('BART (popped)'!F14="FALSO",'BART score'!E14,"") -> 11 | F7: =IF('BART (popped)'!G14="FALSO",'BART score'!F14,"") -> 12 | G7: =IF('BART (popped)'!H14="FALSO",'BART score'!G14,"") -> 13 | H7: =IF('BART (popped)'!I14="FALSO",'BART score'!H14,"") -> 12 | I7: =IF('BART (popped)'!J14="FALSO",'BART score'!I14,"") -> 13 | J7: =IF('BART (popped)'!K14="FALSO",'BART score'!J14,"") | K7: =IF('BART (popped)'!L14="FALSO",'BART score'!K14,"") | ... W7: =IF('BART (popped)'!X14="FALSO",'BART score'!W14,"") -> 8 | X7: =AVERAGE(D7:W7) -> 10.8125
A8: ='BART score'!A15 -> 45490 | B8: ='BART score'!B15 -> 16h01 | C8: ='BART score'!C15 -> MM28031953 | D8: =IF('BART (popped)'!E15="FALSO",'BART score'!D15,"") -> 10 | E8: =IF('BART (popped)'!F15="FALSO",'BART score'!E15,"") -> 10 | F8: =IF('BART (popped)'!G15="FALSO",'BART score'!F15,"") | G8: =IF('BART (popped)'!H15="FALSO",'BART score'!G15,"") -> 10 | H8: =IF('BART (popped)'!I15="FALSO",'BART score'!H15,"") -> 10 | I8: =IF('BART (popped)'!J15="FALSO",'BART score'!I15,"") -> 10 | J8: =IF('BART (popped)'!K15="FALSO",'BART score'!J15,"") -> 10 | K8: =IF('BART (popped)'!L15="FALSO",'BART score'!K15,"") -> 20 | ... W8: =IF('BART (popped)'!X15="FALSO",'BART score'!W15,"") -> 40 | X8: =AVERAGE(D8:W8) -> 21.866667
A9: ='BART score'!A16 -> 45476 | B9: ='BART score'!B16 -> 16h18 | C9: ='BART score'!C16 -> MN10051949 | D9: =IF('BART (popped)'!E16="FALSO",'BART score'!D16,"") -> 10 | E9: =IF('BART (popped)'!F16="FALSO",'BART score'!E16,"") | F9: =IF('BART (popped)'!G16="FALSO",'BART score'!F16,"") -> 8 | G9: =IF('BART (popped)'!H16="FALSO",'BART score'!G16,"") -> 8 | H9: =IF('BART (popped)'!I16="FALSO",'BART score'!H16,"") -> 12 | I9: =IF('BART (popped)'!J16="FALSO",'BART score'!I16,"") -> 16 | J9: =IF('BART (popped)'!K16="FALSO",'BART score'!J16,"") -> 11 | K9: =IF('BART (popped)'!L16="FALSO",'BART score'!K16,"") -> 16 | ... W9: =IF('BART (popped)'!X16="FALSO",'BART score'!W16,"") -> 14 | X9: =AVERAGE(D9:W9) -> 11.052632
A10: ='BART score'!A18 -> 45477 | B10: ='BART score'!B18 -> 14h59 | C10: ='BART score'!C18 -> MR05051963 | D10: =IF('BART (popped)'!E18="FALSO",'BART score'!D18,"") -> 32 | E10: =IF('BART (popped)'!F18="FALSO",'BART score'!E18,"") -> 12 | F10: =IF('BART (popped)'!G18="FALSO",'BART score'!F18,"") -> 16 | G10: =IF('BART (popped)'!H18="FALSO",'BART score'!G18,"") -> 21 | H10: =IF('BART (popped)'!I18="FALSO",'BART score'!H18,"") -> 20 | I10: =IF('BART (popped)'!J18="FALSO",'BART score'!I18,"") -> 23 | J10: =IF('BART (popped)'!K18="FALSO",'BART score'!J18,"") | K10: =IF('BART (popped)'!L18="FALSO",'BART score'!K18,"") -> 20 | ... W10: =IF('BART (popped)'!X18="FALSO",'BART score'!W18,"") -> 16 | X10: =AVERAGE(D10:W10) -> 18.588235
A11: ='BART score'!A19 -> 45484 | B11: ='BART score'!B19 -> 16h34 | C11: ='BART score'!C19 -> MS26011951 | D11: =IF('BART (popped)'!E19="FALSO",'BART score'!D19,"") -> 5 | E11: =IF('BART (popped)'!F19="FALSO",'BART score'!E19,"") -> 10 | F11: =IF('BART (popped)'!G19="FALSO",'BART score'!F19,"") -> 15 | G11: =IF('BART (popped)'!H19="FALSO",'BART score'!G19,"") | H11: =IF('BART (popped)'!I19="FALSO",'BART score'!H19,"") -> 6 | I11: =IF('BART (popped)'!J19="FALSO",'BART score'!I19,"") -> 7 | J11: =IF('BART (popped)'!K19="FALSO",'BART score'!J19,"") -> 9 | K11: =IF('BART (popped)'!L19="FALSO",'BART score'!K19,"") -> 12 | ... W11: =IF('BART (popped)'!X19="FALSO",'BART score'!W19,"") -> 15 | X11: =AVERAGE(D11:W11) -> 12.625
A12: ='BART score'!A20 -> 45485 | B12: ='BART score'!B20 -> 11h42 | C12: ='BART score'!C20 -> OP18061957 | D12: =IF('BART (popped)'!E20="FALSO",'BART score'!D20,"") | E12: =IF('BART (popped)'!F20="FALSO",'BART score'!E20,"") -> 7 | F12: =IF('BART (popped)'!G20="FALSO",'BART score'!F20,"") -> 6 | G12: =IF('BART (popped)'!H20="FALSO",'BART score'!G20,"") -> 15 | H12: =IF('BART (popped)'!I20="FALSO",'BART score'!H20,"") -> 17 | I12: =IF('BART (popped)'!J20="FALSO",'BART score'!I20,"") -> 21 | J12: =IF('BART (popped)'!K20="FALSO",'BART score'!J20,"") -> 28 | K12: =IF('BART (popped)'!L20="FALSO",'BART score'!K20,"") -> 31 | ... W12: =IF('BART (popped)'!X20="FALSO",'BART score'!W20,"") -> 34 | X12: =AVERAGE(D12:W12) -> 25.117647
A13: ='BART score'!A21 -> 45476 | B13: ='BART score'!B21 -> 17h19 | C13: ='BART score'!C21 -> SN02011956 | D13: =IF('BART (popped)'!E21="FALSO",'BART score'!D21,"") -> 3 | E13: =IF('BART (popped)'!F21="FALSO",'BART score'!E21,"") -> 3 | F13: =IF('BART (popped)'!G21="FALSO",'BART score'!F21,"") -> 3 | G13: =IF('BART (popped)'!H21="FALSO",'BART score'!G21,"") -> 4 | H13: =IF('BART (popped)'!I21="FALSO",'BART score'!H21,"") -> 7 | I13: =IF('BART (popped)'!J21="FALSO",'BART score'!I21,"") -> 5 | J13: =IF('BART (popped)'!K21="FALSO",'BART score'!J21,"") -> 4 | K13: =IF('BART (popped)'!L21="FALSO",'BART score'!K21,"") -> 6 | ... W13: =IF('BART (popped)'!X21="FALSO",'BART score'!W21,"") -> 5 | X13: =AVERAGE(D13:W13) -> 5.25
A14: ='BART score'!A23 -> 45476 | B14: ='BART score'!B23 -> 15h27 | C14: ='BART score'!C23 -> MN21031947 | D14: =IF('BART (popped)'!E23="FALSO",'BART score'!D23,"") -> 16 | E14: =IF('BART (popped)'!F23="FALSO",'BART score'!E23,"") -> 16 | F14: =IF('BART (popped)'!G23="FALSO",'BART score'!F23,"") -> 28 | G14: =IF('BART (popped)'!H23="FALSO",'BART score'!G23,"") -> 28 | H14: =IF('BART (popped)'!I23="FALSO",'BART score'!H23,"") -> 29 | I14: =IF('BART (popped)'!J23="FALSO",'BART score'!I23,"") -> 36 | J14: =IF('BART (popped)'!K23="FALSO",'BART score'!J23,"") -> 36 | K14: =IF('BART (popped)'!L23="FALSO",'BART score'!K23,"") -> 32 | ... W14: =IF('BART (popped)'!X23="FALSO",'BART score'!W23,"") -> 26 | X14: =AVERAGE(D14:W14) -> 28.833333
A15: ='BART score'!A24 -> 45545 | B15: ='BART score'!B24 -> 16h23 | C15: ='BART score'!C24 -> AC17101947 | D15: =IF('BART (popped)'!E24="FALSO",'BART score'!D24,"") -> 23 | E15: =IF('BART (popped)'!F24="FALSO",'BART score'!E24,"") -> 16 | F15: =IF('BART (popped)'!G24="FALSO",'BART score'!F24,"") -> 18 | G15: =IF('BART (popped)'!H24="FALSO",'BART score'!G24,"") -> 18 | H15: =IF('BART (popped)'!I24="FALSO",'BART score'!H24,"") -> 23 | I15: =IF('BART (popped)'!J24="FALSO",'BART score'!I24,"") -> 18 | J15: =IF('BART (popped)'!K24="FALSO",'BART score'!J24,"") -> 20 | K15: =IF('BART (popped)'!L24="FALSO",'BART score'!K24,"") -> 25 | ... W15: =IF('BART (popped)'!X24="FALSO",'BART score'!W24,"") -> 21 | X15: =AVERAGE(D15:W15) -> 21.052632
A16: ='BART score'!A25 -> 45504 | B16: ='BART score'!B25 -> 15h39 | C16: ='BART score'!C25 -> AO25031956 | D16: =IF('BART (popped)'!E25="FALSO",'BART score'!D25,"") -> 7 | E16: =IF('BART (popped)'!F25="FALSO",'BART score'!E25,"") -> 11 | F16: =IF('BART (popped)'!G25="FALSO",'BART score'!F25,"") -> 14 | G16: =IF('BART (popped)'!H25="FALSO",'BART score'!G25,"") | H16: =IF('BART (popped)'!I25="FALSO",'BART score'!H25,"") -> 13 | I16: =IF('BART (popped)'!J25="FALSO",'BART score'!I25,"") -> 9 | J16: =IF('BART (popped)'!K25="FALSO",'BART score'!J25,"") -> 6 | K16: =IF('BART (popped)'!L25="FALSO",'BART score'!K25,"") -> 6 | ... W16: =IF('BART (popped)'!X25="FALSO",'BART score'!W25,"") -> 3 | X16: =AVERAGE(D16:W16) -> 6.3157895
A17: ='BART score'!A27 -> 45506 | B17: ='BART score'!B27 -> 15h41 | C17: ='BART score'!C27 -> MF28091947 | D17: =IF('BART (popped)'!E27="FALSO",'BART score'!D27,"") | E17: =IF('BART (popped)'!F27="FALSO",'BART score'!E27,"") -> 16 | F17: =IF('BART (popped)'!G27="FALSO",'BART score'!F27,"") -> 12 | G17: =IF('BART (popped)'!H27="FALSO",'BART score'!G27,"") -> 19 | H17: =IF('BART (popped)'!I27="FALSO",'BART score'!H27,"") | I17: =IF('BART (popped)'!J27="FALSO",'BART score'!I27,"") -> 9 | J17: =IF('BART (popped)'!K27="FALSO",'BART score'!J27,"") -> 14 | K17: =IF('BART (popped)'!L27="FALSO",'BART score'!K27,"") -> 11 | ... W17: =IF('BART (popped)'!X27="FALSO",'BART score'!W27,"") -> 20 | X17: =AVERAGE(D17:W17) -> 16
A18: ='BART score'!A29 | B18: ='BART score'!B29 | C18: ='BART score'!C29 | D18: =IF('BART (popped)'!E29="FALSO",'BART score'!D29,"") | E18: =IF('BART (popped)'!F29="FALSO",'BART score'!E29,"") | F18: =IF('BART (popped)'!G29="FALSO",'BART score'!F29,"") | G18: =IF('BART (popped)'!H29="FALSO",'BART score'!G29,"") | H18: =IF('BART (popped)'!I29="FALSO",'BART score'!H29,"") | I18: =IF('BART (popped)'!J29="FALSO",'BART score'!I29,"") | J18: =IF('BART (popped)'!K29="FALSO",'BART score'!J29,"") | K18: =IF('BART (popped)'!L29="FALSO",'BART score'!K29,"") | ... W18: =IF('BART (popped)'!X29="FALSO",'BART score'!W29,"")
A19: ='BART score'!A30 | B19: ='BART score'!B30 | C19: ='BART score'!C30 | D19: =IF('BART (popped)'!E30="FALSO",'BART score'!D30,"") | E19: =IF('BART (popped)'!F30="FALSO",'BART score'!E30,"") | F19: =IF('BART (popped)'!G30="FALSO",'BART score'!F30,"") | G19: =IF('BART (popped)'!H30="FALSO",'BART score'!G30,"") | H19: =IF('BART (popped)'!I30="FALSO",'BART score'!H30,"") | I19: =IF('BART (popped)'!J30="FALSO",'BART score'!I30,"") | J19: =IF('BART (popped)'!K30="FALSO",'BART score'!J30,"") | K19: =IF('BART (popped)'!L30="FALSO",'BART score'!K30,"") | ... W19: =IF('BART (popped)'!X30="FALSO",'BART score'!W30,"")
A20: ='BART score'!A31 | B20: ='BART score'!B31 | C20: ='BART score'!C31 | D20: =IF('BART (popped)'!E31="FALSO",'BART score'!D31,"") | E20: =IF('BART (popped)'!F31="FALSO",'BART score'!E31,"") | F20: =IF('BART (popped)'!G31="FALSO",'BART score'!F31,"") | G20: =IF('BART (popped)'!H31="FALSO",'BART score'!G31,"") | H20: =IF('BART (popped)'!I31="FALSO",'BART score'!H31,"") | I20: =IF('BART (popped)'!J31="FALSO",'BART score'!I31,"") | J20: =IF('BART (popped)'!K31="FALSO",'BART score'!J31,"") | K20: =IF('BART (popped)'!L31="FALSO",'BART score'!K31,"") | ... W20: =IF('BART (popped)'!X31="FALSO",'BART score'!W31,"")
A21: ='BART score'!A32 | B21: ='BART score'!B32 | C21: ='BART score'!C32 | D21: =IF('BART (popped)'!E32="FALSO",'BART score'!D32,"") | E21: =IF('BART (popped)'!F32="FALSO",'BART score'!E32,"") | F21: =IF('BART (popped)'!G32="FALSO",'BART score'!F32,"") | G21: =IF('BART (popped)'!H32="FALSO",'BART score'!G32,"") | H21: =IF('BART (popped)'!I32="FALSO",'BART score'!H32,"") | I21: =IF('BART (popped)'!J32="FALSO",'BART score'!I32,"") | J21: =IF('BART (popped)'!K32="FALSO",'BART score'!J32,"") | K21: =IF('BART (popped)'!L32="FALSO",'BART score'!K32,"") | ... W21: =IF('BART (popped)'!X32="FALSO",'BART score'!W32,"")
A22: ='BART score'!A33 | B22: ='BART score'!B33 | C22: ='BART score'!C33 | D22: =IF('BART (popped)'!E33="FALSO",'BART score'!D33,"") | E22: =IF('BART (popped)'!F33="FALSO",'BART score'!E33,"") | F22: =IF('BART (popped)'!G33="FALSO",'BART score'!F33,"") | G22: =IF('BART (popped)'!H33="FALSO",'BART score'!G33,"") | H22: =IF('BART (popped)'!I33="FALSO",'BART score'!H33,"") | I22: =IF('BART (popped)'!J33="FALSO",'BART score'!I33,"") | J22: =IF('BART (popped)'!K33="FALSO",'BART score'!J33,"") | K22: =IF('BART (popped)'!L33="FALSO",'BART score'!K33,"") | ... W22: =IF('BART (popped)'!X33="FALSO",'BART score'!W33,"")
A23: ='BART score'!A34 | B23: ='BART score'!B34 | C23: ='BART score'!C34 | D23: =IF('BART (popped)'!E34="FALSO",'BART score'!D34,"") | E23: =IF('BART (popped)'!F34="FALSO",'BART score'!E34,"") | F23: =IF('BART (popped)'!G34="FALSO",'BART score'!F34,"") | G23: =IF('BART (popped)'!H34="FALSO",'BART score'!G34,"") | H23: =IF('BART (popped)'!I34="FALSO",'BART score'!H34,"") | I23: =IF('BART (popped)'!J34="FALSO",'BART score'!I34,"") | J23: =IF('BART (popped)'!K34="FALSO",'BART score'!J34,"") | K23: =IF('BART (popped)'!L34="FALSO",'BART score'!K34,"") | ... W23: =IF('BART (popped)'!X34="FALSO",'BART score'!W34,"")
A24: ='BART score'!A35 | B24: ='BART score'!B35 | C24: ='BART score'!C35 | D24: =IF('BART (popped)'!E35="FALSO",'BART score'!D35,"") | E24: =IF('BART (popped)'!F35="FALSO",'BART score'!E35,"") | F24: =IF('BART (popped)'!G35="FALSO",'BART score'!F35,"") | G24: =IF('BART (popped)'!H35="FALSO",'BART score'!G35,"") | H24: =IF('BART (popped)'!I35="FALSO",'BART score'!H35,"") | I24: =IF('BART (popped)'!J35="FALSO",'BART score'!I35,"") | J24: =IF('BART (popped)'!K35="FALSO",'BART score'!J35,"") | K24: =IF('BART (popped)'!L35="FALSO",'BART score'!K35,"") | ... W24: =IF('BART (popped)'!X35="FALSO",'BART score'!W35,"")
A25: ='BART score'!A36 | B25: ='BART score'!B36 | C25: ='BART score'!C36 | D25: =IF('BART (popped)'!E36="FALSO",'BART score'!D36,"") | E25: =IF('BART (popped)'!F36="FALSO",'BART score'!E36,"") | F25: =IF('BART (popped)'!G36="FALSO",'BART score'!F36,"") | G25: =IF('BART (popped)'!H36="FALSO",'BART score'!G36,"") | H25: =IF('BART (popped)'!I36="FALSO",'BART score'!H36,"") | I25: =IF('BART (popped)'!J36="FALSO",'BART score'!I36,"") | J25: =IF('BART (popped)'!K36="FALSO",'BART score'!J36,"") | K25: =IF('BART (popped)'!L36="FALSO",'BART score'!K36,"") | ... W25: =IF('BART (popped)'!X36="FALSO",'BART score'!W36,"")
A26: ='BART score'!A37 | B26: ='BART score'!B37 | C26: ='BART score'!C37 | D26: =IF('BART (popped)'!E37="FALSO",'BART score'!D37,"") | E26: =IF('BART (popped)'!F37="FALSO",'BART score'!E37,"") | F26: =IF('BART (popped)'!G37="FALSO",'BART score'!F37,"") | G26: =IF('BART (popped)'!H37="FALSO",'BART score'!G37,"") | H26: =IF('BART (popped)'!I37="FALSO",'BART score'!H37,"") | I26: =IF('BART (popped)'!J37="FALSO",'BART score'!I37,"") | J26: =IF('BART (popped)'!K37="FALSO",'BART score'!J37,"") | K26: =IF('BART (popped)'!L37="FALSO",'BART score'!K37,"") | ... W26: =IF('BART (popped)'!X37="FALSO",'BART score'!W37,"")
A27: ='BART score'!A38 | B27: ='BART score'!B38 | C27: ='BART score'!C38 | D27: =IF('BART (popped)'!E38="FALSO",'BART score'!D38,"") | E27: =IF('BART (popped)'!F38="FALSO",'BART score'!E38,"") | F27: =IF('BART (popped)'!G38="FALSO",'BART score'!F38,"") | G27: =IF('BART (popped)'!H38="FALSO",'BART score'!G38,"") | H27: =IF('BART (popped)'!I38="FALSO",'BART score'!H38,"") | I27: =IF('BART (popped)'!J38="FALSO",'BART score'!I38,"") | J27: =IF('BART (popped)'!K38="FALSO",'BART score'!J38,"") | K27: =IF('BART (popped)'!L38="FALSO",'BART score'!K38,"") | ... W27: =IF('BART (popped)'!X38="FALSO",'BART score'!W38,"")
A28: ='BART score'!A39 | B28: ='BART score'!B39 | C28: ='BART score'!C39 | D28: =IF('BART (popped)'!E39="FALSO",'BART score'!D39,"") | E28: =IF('BART (popped)'!F39="FALSO",'BART score'!E39,"") | F28: =IF('BART (popped)'!G39="FALSO",'BART score'!F39,"") | G28: =IF('BART (popped)'!H39="FALSO",'BART score'!G39,"") | H28: =IF('BART (popped)'!I39="FALSO",'BART score'!H39,"") | I28: =IF('BART (popped)'!J39="FALSO",'BART score'!I39,"") | J28: =IF('BART (popped)'!K39="FALSO",'BART score'!J39,"") | K28: =IF('BART (popped)'!L39="FALSO",'BART score'!K39,"") | ... W28: =IF('BART (popped)'!X39="FALSO",'BART score'!W39,"")
A29: ='BART score'!A40 | B29: ='BART score'!B40 | C29: ='BART score'!C40 | D29: =IF('BART (popped)'!E40="FALSO",'BART score'!D40,"") | E29: =IF('BART (popped)'!F40="FALSO",'BART score'!E40,"") | F29: =IF('BART (popped)'!G40="FALSO",'BART score'!F40,"") | G29: =IF('BART (popped)'!H40="FALSO",'BART score'!G40,"") | H29: =IF('BART (popped)'!I40="FALSO",'BART score'!H40,"") | I29: =IF('BART (popped)'!J40="FALSO",'BART score'!I40,"") | J29: =IF('BART (popped)'!K40="FALSO",'BART score'!J40,"") | K29: =IF('BART (popped)'!L40="FALSO",'BART score'!K40,"") | ... W29: =IF('BART (popped)'!X40="FALSO",'BART score'!W40,"")
... A36: ='BART score'!A47 | B36: ='BART score'!B47 | C36: ='BART score'!C47 | D36: =IF('BART (popped)'!E47="FALSO",'BART score'!D47,"") | E36: =IF('BART (popped)'!F47="FALSO",'BART score'!E47,"") | F36: =IF('BART (popped)'!G47="FALSO",'BART score'!F47,"") | G36: =IF('BART (popped)'!H47="FALSO",'BART score'!G47,"") | H36: =IF('BART (popped)'!I47="FALSO",'BART score'!H47,"") | I36: =IF('BART (popped)'!J47="FALSO",'BART score'!I47,"") | J36: =IF('BART (popped)'!K47="FALSO",'BART score'!J47,"") | K36: =IF('BART (popped)'!L47="FALSO",'BART score'!K47,"") | ... W36: =IF('BART (popped)'!X47="FALSO",'BART score'!W47,"")
A37: ='BART score'!A48 | B37: ='BART score'!B48 | C37: ='BART score'!C48 | E37: =IF('BART (popped)'!F48="FALSO",'BART score'!E48,"") | F37: =IF('BART (popped)'!G48="FALSO",'BART score'!F48,"") | G37: =IF('BART (popped)'!H48="FALSO",'BART score'!G48,"") | H37: =IF('BART (popped)'!I48="FALSO",'BART score'!H48,"") | I37: =IF('BART (popped)'!J48="FALSO",'BART score'!I48,"") | J37: =IF('BART (popped)'!K48="FALSO",'BART score'!J48,"") | K37: =IF('BART (popped)'!L48="FALSO",'BART score'!K48,"") | L37: =IF('BART (popped)'!M48="FALSO",'BART score'!L48,"") | ... W37: =IF('BART (popped)'!X48="FALSO",'BART score'!W48,"")
A38: ='BART score'!A49 | B38: ='BART score'!B49 | C38: ='BART score'!C49 | E38: =IF('BART (popped)'!F49="FALSO",'BART score'!E49,"") | F38: =IF('BART (popped)'!G49="FALSO",'BART score'!F49,"") | G38: =IF('BART (popped)'!H49="FALSO",'BART score'!G49,"") | H38: =IF('BART (popped)'!I49="FALSO",'BART score'!H49,"") | I38: =IF('BART (popped)'!J49="FALSO",'BART score'!I49,"") | J38: =IF('BART (popped)'!K49="FALSO",'BART score'!J49,"") | K38: =IF('BART (popped)'!L49="FALSO",'BART score'!K49,"") | L38: =IF('BART (popped)'!M49="FALSO",'BART score'!L49,"") | ... W38: =IF('BART (popped)'!X49="FALSO",'BART score'!W49,"")
A39: ='BART score'!A50 | B39: ='BART score'!B50 | C39: ='BART score'!C50 | E39: =IF('BART (popped)'!F50="FALSO",'BART score'!E50,"") | F39: =IF('BART (popped)'!G50="FALSO",'BART score'!F50,"") | G39: =IF('BART (popped)'!H50="FALSO",'BART score'!G50,"") | H39: =IF('BART (popped)'!I50="FALSO",'BART score'!H50,"") | I39: =IF('BART (popped)'!J50="FALSO",'BART score'!I50,"") | J39: =IF('BART (popped)'!K50="FALSO",'BART score'!J50,"") | K39: =IF('BART (popped)'!L50="FALSO",'BART score'!K50,"") | L39: =IF('BART (popped)'!M50="FALSO",'BART score'!L50,"") | ... W39: =IF('BART (popped)'!X50="FALSO",'BART score'!W50,"")
A40: ='BART score'!A51 | B40: ='BART score'!B51 | C40: ='BART score'!C51 | E40: =IF('BART (popped)'!F51="FALSO",'BART score'!E51,"") | F40: =IF('BART (popped)'!G51="FALSO",'BART score'!F51,"") | G40: =IF('BART (popped)'!H51="FALSO",'BART score'!G51,"") | H40: =IF('BART (popped)'!I51="FALSO",'BART score'!H51,"") | I40: =IF('BART (popped)'!J51="FALSO",'BART score'!I51,"") | J40: =IF('BART (popped)'!K51="FALSO",'BART score'!J51,"") | K40: =IF('BART (popped)'!L51="FALSO",'BART score'!K51,"") | L40: =IF('BART (popped)'!M51="FALSO",'BART score'!L51,"") | ... W40: =IF('BART (popped)'!X51="FALSO",'BART score'!W51,"")
A41: ='BART score'!A52 | B41: ='BART score'!B52 | C41: ='BART score'!C52 | E41: =IF('BART (popped)'!F52="FALSO",'BART score'!E52,"") | F41: =IF('BART (popped)'!G52="FALSO",'BART score'!F52,"") | G41: =IF('BART (popped)'!H52="FALSO",'BART score'!G52,"") | H41: =IF('BART (popped)'!I52="FALSO",'BART score'!H52,"") | I41: =IF('BART (popped)'!J52="FALSO",'BART score'!I52,"") | J41: =IF('BART (popped)'!K52="FALSO",'BART score'!J52,"") | K41: =IF('BART (popped)'!L52="FALSO",'BART score'!K52,"") | L41: =IF('BART (popped)'!M52="FALSO",'BART score'!L52,"") | ... W41: =IF('BART (popped)'!X52="FALSO",'BART score'!W52,"")
A42: ='BART score'!A53 | B42: ='BART score'!B53 | C42: ='BART score'!C53 | E42: =IF('BART (popped)'!F53="FALSO",'BART score'!E53,"") | F42: =IF('BART (popped)'!G53="FALSO",'BART score'!F53,"") | G42: =IF('BART (popped)'!H53="FALSO",'BART score'!G53,"") | H42: =IF('BART (popped)'!I53="FALSO",'BART score'!H53,"") | I42: =IF('BART (popped)'!J53="FALSO",'BART score'!I53,"") | J42: =IF('BART (popped)'!K53="FALSO",'BART score'!J53,"") | K42: =IF('BART (popped)'!L53="FALSO",'BART score'!K53,"") | L42: =IF('BART (popped)'!M53="FALSO",'BART score'!L53,"") | ... W42: =IF('BART (popped)'!X53="FALSO",'BART score'!W53,"")
A43: ='BART score'!A54 | B43: ='BART score'!B54 | C43: ='BART score'!C54 | E43: =IF('BART (popped)'!F54="FALSO",'BART score'!E54,"") | F43: =IF('BART (popped)'!G54="FALSO",'BART score'!F54,"") | G43: =IF('BART (popped)'!H54="FALSO",'BART score'!G54,"") | H43: =IF('BART (popped)'!I54="FALSO",'BART score'!H54,"") | I43: =IF('BART (popped)'!J54="FALSO",'BART score'!I54,"") | J43: =IF('BART (popped)'!K54="FALSO",'BART score'!J54,"") | K43: =IF('BART (popped)'!L54="FALSO",'BART score'!K54,"") | L43: =IF('BART (popped)'!M54="FALSO",'BART score'!L54,"") | ... W43: =IF('BART (popped)'!X54="FALSO",'BART score'!W54,"")
A44: ='BART score'!A55 | B44: ='BART score'!B55 | C44: ='BART score'!C55
A45: ='BART score'!A56 | B45: ='BART score'!B56 | C45: ='BART score'!C56
A46: ='BART score'!A57 | B46: ='BART score'!B57 | C46: ='BART score'!C57
...
